<?xml version="1.0" encoding="UTF-8"?>
<!-- Generated by org.testng.reporters.JUnitReportReporter -->
<testsuite hostname="hfuopen398.hfu-open.fu.hs-furtwangen.de" name="com.xcellent.challenge.CIDIRTest" tests="1" failures="0" timestamp="24 Nov 2011 17:12:15 GMT" time="0.015" errors="1">
  <testcase name="testCidr" time="0.015" classname="com.xcellent.challenge.CIDIRTest">
    <error type="java.lang.AssertionError" message="expected:&lt;127.0.0.1/8&gt; but was:&lt;127.0.0.1/8&gt;">
      <![CDATA[java.lang.AssertionError: expected:<127.0.0.1/8> but was:<127.0.0.1/8>
	at org.testng.AssertJUnit.fail(AssertJUnit.java:59)
	at org.testng.AssertJUnit.failNotEquals(AssertJUnit.java:364)
	at org.testng.AssertJUnit.assertEquals(AssertJUnit.java:80)
	at org.testng.AssertJUnit.assertEquals(AssertJUnit.java:88)
	at com.xcellent.challenge.CIDIRTest.testCidr(CIDIRTest.java:27)
	at sun.reflect.NativeMethodAccessorImpl.invoke0(Native Method)
	at sun.reflect.NativeMethodAccessorImpl.invoke(NativeMethodAccessorImpl.java:39)
	at sun.reflect.DelegatingMethodAccessorImpl.invoke(DelegatingMethodAccessorImpl.java:25)
	at java.lang.reflect.Method.invoke(Method.java:597)
	at org.testng.internal.MethodInvocationHelper.invokeMethod(MethodInvocationHelper.java:80)
	at org.testng.internal.Invoker.invokeMethod(Invoker.java:691)
	at org.testng.internal.Invoker.invokeTestMethod(Invoker.java:883)
	at org.testng.internal.Invoker.invokeTestMethods(Invoker.java:1208)
	at org.testng.internal.TestMethodWorker.invokeTestMethods(TestMethodWorker.java:127)
	at org.testng.internal.TestMethodWorker.run(TestMethodWorker.java:111)
	at org.testng.TestRunner.privateRun(TestRunner.java:758)
	at org.testng.TestRunner.run(TestRunner.java:613)
	at org.testng.SuiteRunner.runTest(SuiteRunner.java:334)
	at org.testng.SuiteRunner.runSequentially(SuiteRunner.java:329)
	at org.testng.SuiteRunner.privateRun(SuiteRunner.java:291)
	at org.testng.SuiteRunner.run(SuiteRunner.java:240)
	at org.testng.SuiteRunnerWorker.runSuite(SuiteRunnerWorker.java:53)
	at org.testng.SuiteRunnerWorker.run(SuiteRunnerWorker.java:87)
	at org.testng.TestNG.runSuitesSequentially(TestNG.java:1137)
	at org.testng.TestNG.runSuitesLocally(TestNG.java:1062)
	at org.testng.TestNG.run(TestNG.java:974)
	at org.testng.remote.RemoteTestNG.run(RemoteTestNG.java:109)
	at org.testng.remote.RemoteTestNG.initAndRun(RemoteTestNG.java:202)
	at org.testng.remote.RemoteTestNG.main(RemoteTestNG.java:173)
]]>
    </error>
  </testcase>
</testsuite>
